<mujoco>
	<compiler angle="radian"
			inertiafromgeom="auto"
			texturedir="textures/"/>
	<option timestep="2e-3"
			iterations="35"
			tolerance="1e-10"
			impratio="20"
			cone="elliptic" />
	<size njmax="10000" nconmax="5000" nstack="15000000"/>

	<asset>
		<!--Textures-->
		<texture name="ur5_tex"     type="2d"       builtin="flat" height="32" width="32" rgb1=".3 .3 .3" />
		<texture name="gripper_tex" type="2d"       builtin="flat" height="32" width="32" rgb1="0.45 0.45 0.45" rgb2="0 0 0"/>
		<texture name="bench_tex"   type="2d"       builtin="flat" height="32" width="32" rgb1="0.7 0.7 0.7" />
		<texture name="sky_tex"     type="skybox"   builtin="gradient" width="100" height="100" rgb1="1 1 1" rgb2="0.3 0.3 0.8" />
		<texture name="texgeom"     type="cube"     builtin="flat" mark="cross" width="127" height="1278" rgb1="0.8 0.6 0.4" rgb2="0.8 0.6 0.4" markrgb="1 1 1" random="0.01" />
		<texture name="floor_tex"   type="2d"        builtin="checker" rgb1=".3 .4 .5" rgb2=".2 .3 .4" width="100" height="100" />
		<texture name="wood"        type="cube"     file="wood2.png"/>
		<texture name="metal"        type="cube"     file="metal2.png"/>
		<!--Materials-->
		<material name="ur5_mat"        texture="ur5_tex"   shininess="0.9" specular="0.75" reflectance="0.3"/>
		<material name="gripper_mat"    texture="gripper_tex"   shininess="0.9" specular="0.75" reflectance="0.4"/>
		<material name='floor_mat'      texture="floor_tex"  shininess="0.8" texrepeat="10 10" specular="0.7"  reflectance="0.05" />
		<material name='geom'           texture="texgeom"   texuniform="true" />
		<material name="bench_mat"      texture="metal"   shininess="0.1" specular="0.5" reflectance="0.2"/>
		<material name="tablecube"      texture="wood" rgba=".8 .8 .8 1"/>
  		
  		<mesh file='rover.stl' name="rover" scale='0.01 0.01 0.01' />
  		<mesh file="4WDCore.stl" name="core"/>
  		<mesh file="LeftRearWheel.stl" name="left_rear" />
  		<mesh file="RightFrontWheel.stl" name="right_front" />
  		<mesh file="LeftFrontWheel.stl" name="left_front" />
  		<mesh file="RightRearWheel.stl" name="right_rear" />
   
	</asset>

	<default>
		<geom contype='1' conaffinity='1' condim='6' solref="6e-3 2" solimp=".99 .995 .01" friction="0.5 0.01 0.0005" rgba="0.8 0.8 0.8 1" />
		<joint damping='0.05' frictionloss='0.3'/>
		<default class="Objects">
			<joint type='free' damping='0.05' />
		</default>
		<default class="World">
			<geom condim='6' solref="5e-3 1.4" solimp=".99 .995 .01" friction="0.9 0.005 0.0001" />
		</default>
	</default>

	<visual>
		<map fogstart="3" fogend="5" znear="0.01" shadowclip='0.6' />
		<quality shadowsize="16384"/>
		<scale  framelength=".2"
		framewidth="0.01"
		contactwidth="1.1"
		contactheight="0.01"
		forcewidth="0.01"
		/>
	</visual>

	<worldbody>
		<!--Lighting parameters-->
		<!-- <light name="light1" directional="true" pos="0 0 20" dir='0 0 -1' /> -->
		<light name="light1" pos="0 0 100" dir='0 0 -1' />

		<geom type='capsule' size='0.2 1' pos='-19 -20 0' rgba='1 0 0 1' quat='0.7071068  0 0.7071068 0' />
		<geom type='capsule' size='0.2 1' pos='-20 -19 0' rgba='0 1 0 1' quat='0.7071068  0.7071068 0 0' />
		<geom type='capsule' size='0.2 1' pos='-20 -20 1' rgba='0 0 1 1' />

		<!--Floor Property-->
		<geom name='floor' pos='0 0 -2' size='20 20 0.1'  type='plane' material="floor_mat" class="World" />
		
		<!-- Fixed Camera -->
		<camera name='c1' fovy="6" pos="0 0 100" euler="0 0 0" >
		</camera>

		<camera name='c2' fovy="40" pos="-14 -13 15" euler="0.8 -0.8 -.5" >
		</camera>

		<body name="rover" pos="0 0 0" >
			<joint name="rover" type="free"/>
			<geom material="ur5_mat" mesh="rover" name="rover" type="mesh" quat="0.7071068 0.7071068 0 0"/>
			
			<!-- platform pillars -->
			<geom type="cylinder" fromto=" 0.795 0     0.5  0.795 0     1.48" size="0.05 0.4"/>
			<geom type="cylinder" fromto="-0.795 0     0.5 -0.795 0     1.48" size="0.05 0.4"/>
			<geom type="cylinder" fromto=" 0.795 2.835 0.5  0.795 2.835 1.48" size="0.05 0.4"/>
			<geom type="cylinder" fromto="-0.795 2.835 0.5 -0.795 2.835 1.48" size="0.05 0.4"/>
			
			<!-- platform board -->
			<geom name="platform" type="box" pos="0 1.4 1.495" size="1.8 2.5 0.05" rgba="1 1 1 0.3" />
			
			<geom name="slider_base" type="box" pos="1.3 2 1.55" size="0.2 1 0.05"/>
			<body name="laser_slider" pos="1.3 2 1.6" >
				<joint name="laser_slider" type="slide" pos="0 1 0.05" axis="0 1 0" damping="45" limited="true" range="-1 1" />
				<geom type="box" pos="0 0 0.41" size="0.2 0.2 0.39" />
				<geom type="box" pos="-0.2 0 1" size="0.4 0.2 0.2" />
				<body name="laser_rotor" pos="0 0.45 1">
					<joint name="laser_rotor" type="hinge" axis="0 1 0" damping="15" limited="true" range="-3.14159 3.14159" />
					
					<geom type='cylinder' fromto="0 -0.25 0 0 -0.05 0" size="0.4" />
					<geom name='laser' type='cylinder' fromto="-0.27 0 0.27 0.27 0 -0.27" size="0.1" />
					<geom name="beam" type='cylinder' fromto="0 0 0 7 0 -7" size="0.02" density="0.00001" contype="0" conaffinity="0" rgba="1 0 0 1" />
				</body>
			</body>

			<body name="camera_base" pos="1.3 0 1.6">
				<geom type="box" pos="0.2 0.3 0" size="0.3 0.3 0.05" rgba="1 0.7 0 1" />
				<body name="camera" pos="0.8 0.3 0.3" quat="0.3826834 0 0.9238795  0" >
					<geom type="box" size="0.45 0.3 0.05" rgba="1 0.7 0 1" />
					<geom type="box" pos="-0.3 0 0.15" size="0.1 0.35 0.1" />
					<geom type="cylinder" pos="-0.3 0 0.25" size="0.1 0.02" rgba="0 0 0 1" />
					<camera name='c3' fovy="90" pos="0 0 0.1" euler="3.14159 0 1.5708" >
					</camera>
				</body>
			</body>
		</body>

		<body name="corn_0" pos="6 -6 -1.7" >
			<geom type="cylinder" size="0.2 0.3" rgba="0 1 0 1" />
			<geom type="cylinder" pos="0 -4 0" size="0.2 0.3" rgba="0 1 0 1" />
			<geom type="cylinder" pos="0 4 0" size="0.2 0.3" rgba="0 1 0 1" />
			<geom type="cylinder" pos="0 8 0" size="0.2 0.3" rgba="0 1 0 1" />
			<geom type="cylinder" pos="0 12 0" size="0.2 0.3" rgba="0 1 0 1" />
			<!-- weed -->
			<geom name="weed_0" type="cylinder" pos="0.8 -2.3 0" size="0.1 0.3" rgba="1 1 0.2 1" />
			<geom name="weed_1" type="cylinder" pos="-0.8 5.1 0" size="0.1 0.3" rgba="1 1 0.2 1" />
			<geom name="weed_2" type="cylinder" pos="0.3 2 0" size="0.1 0.3" rgba="1 1 0.2 1" />
			<geom name="weed_3" type="cylinder" pos="1.3 0.7 0" size="0.1 0.3" rgba="1 1 0.2 1" />			
		</body>

		<body name="corn_1" pos="-4 -6 -1.7" >
			<geom type="cylinder" pos="0 -4 0" size="0.2 0.3" rgba="0 1 0 1" />
			<geom type="cylinder" pos="0 0 0" size="0.2 0.3" rgba="0 1 0 1" />
			<geom type="cylinder" pos="0 4 0" size="0.2 0.3" rgba="0 1 0 1" />
			<geom type="cylinder" pos="0 8 0" size="0.2 0.3" rgba="0 1 0 1" />
			<geom type="cylinder" pos="0 12 0" size="0.2 0.3" rgba="0 1 0 1" />
		</body>

	</worldbody>

	<actuator>
		<position name="laser_slider" ctrllimited="true" ctrlrange="-1 1" joint="laser_slider" kp="100" />
		<position name="laser_rotor" ctrllimited="true" ctrlrange="-1 1" joint="laser_rotor" kp="100"/>	
	</actuator>

</mujoco>